2024-11-29 07:35:25,556 - Error occurred: Message: Unable to obtain driver for chrome; For documentation on this error, please visit: https://www.selenium.dev/documentation/webdriver/troubleshooting/errors/driver_location

2024-11-29 07:35:25,557 - Stack trace: Traceback (most recent call last):
  File "C:\Users\taois\scoop\apps\anaconda3\current\App\Lib\site-packages\selenium\webdriver\common\driver_finder.py", line 64, in _binary_paths
    raise ValueError(f"The path is not a valid file: {path}")
ValueError: The path is not a valid file: C:/Users/User/scoop/apps/chromedriver/current/chromedriver.exe

The above exception was the direct cause of the following exception:

Traceback (most recent call last):
  File "D:\EDA\e2\EDA\p.py", line 155, in <module>
    driver = webdriver.Chrome(service=service, options=options)
             ^^^^^^^^^^^^^^^^^^^^^^^^^^^^^^^^^^^^^^^^^^^^^^^^^^
  File "C:\Users\taois\scoop\apps\anaconda3\current\App\Lib\site-packages\selenium\webdriver\chrome\webdriver.py", line 45, in __init__
    super().__init__(
  File "C:\Users\taois\scoop\apps\anaconda3\current\App\Lib\site-packages\selenium\webdriver\chromium\webdriver.py", line 50, in __init__
    if finder.get_browser_path():
       ^^^^^^^^^^^^^^^^^^^^^^^^^
  File "C:\Users\taois\scoop\apps\anaconda3\current\App\Lib\site-packages\selenium\webdriver\common\driver_finder.py", line 47, in get_browser_path
    return self._binary_paths()["browser_path"]
           ^^^^^^^^^^^^^^^^^^^^
  File "C:\Users\taois\scoop\apps\anaconda3\current\App\Lib\site-packages\selenium\webdriver\common\driver_finder.py", line 78, in _binary_paths
    raise NoSuchDriverException(msg) from err
selenium.common.exceptions.NoSuchDriverException: Message: Unable to obtain driver for chrome; For documentation on this error, please visit: https://www.selenium.dev/documentation/webdriver/troubleshooting/errors/driver_location


2024-11-29 07:35:25,558 - Restarting the process...
2024-11-29 07:35:30,562 - Error occurred: Message: Unable to obtain driver for chrome; For documentation on this error, please visit: https://www.selenium.dev/documentation/webdriver/troubleshooting/errors/driver_location

2024-11-29 07:35:30,563 - Stack trace: Traceback (most recent call last):
  File "C:\Users\taois\scoop\apps\anaconda3\current\App\Lib\site-packages\selenium\webdriver\common\driver_finder.py", line 64, in _binary_paths
    raise ValueError(f"The path is not a valid file: {path}")
ValueError: The path is not a valid file: C:/Users/User/scoop/apps/chromedriver/current/chromedriver.exe

The above exception was the direct cause of the following exception:

Traceback (most recent call last):
  File "D:\EDA\e2\EDA\p.py", line 155, in <module>
    driver = webdriver.Chrome(service=service, options=options)
             ^^^^^^^^^^^^^^^^^^^^^^^^^^^^^^^^^^^^^^^^^^^^^^^^^^
  File "C:\Users\taois\scoop\apps\anaconda3\current\App\Lib\site-packages\selenium\webdriver\chrome\webdriver.py", line 45, in __init__
    super().__init__(
  File "C:\Users\taois\scoop\apps\anaconda3\current\App\Lib\site-packages\selenium\webdriver\chromium\webdriver.py", line 50, in __init__
    if finder.get_browser_path():
       ^^^^^^^^^^^^^^^^^^^^^^^^^
  File "C:\Users\taois\scoop\apps\anaconda3\current\App\Lib\site-packages\selenium\webdriver\common\driver_finder.py", line 47, in get_browser_path
    return self._binary_paths()["browser_path"]
           ^^^^^^^^^^^^^^^^^^^^
  File "C:\Users\taois\scoop\apps\anaconda3\current\App\Lib\site-packages\selenium\webdriver\common\driver_finder.py", line 78, in _binary_paths
    raise NoSuchDriverException(msg) from err
selenium.common.exceptions.NoSuchDriverException: Message: Unable to obtain driver for chrome; For documentation on this error, please visit: https://www.selenium.dev/documentation/webdriver/troubleshooting/errors/driver_location


2024-11-29 07:35:30,563 - Restarting the process...
2024-11-29 07:35:35,568 - Error occurred: Message: Unable to obtain driver for chrome; For documentation on this error, please visit: https://www.selenium.dev/documentation/webdriver/troubleshooting/errors/driver_location

2024-11-29 07:35:35,569 - Stack trace: Traceback (most recent call last):
  File "C:\Users\taois\scoop\apps\anaconda3\current\App\Lib\site-packages\selenium\webdriver\common\driver_finder.py", line 64, in _binary_paths
    raise ValueError(f"The path is not a valid file: {path}")
ValueError: The path is not a valid file: C:/Users/User/scoop/apps/chromedriver/current/chromedriver.exe

The above exception was the direct cause of the following exception:

Traceback (most recent call last):
  File "D:\EDA\e2\EDA\p.py", line 155, in <module>
    driver = webdriver.Chrome(service=service, options=options)
             ^^^^^^^^^^^^^^^^^^^^^^^^^^^^^^^^^^^^^^^^^^^^^^^^^^
  File "C:\Users\taois\scoop\apps\anaconda3\current\App\Lib\site-packages\selenium\webdriver\chrome\webdriver.py", line 45, in __init__
    super().__init__(
  File "C:\Users\taois\scoop\apps\anaconda3\current\App\Lib\site-packages\selenium\webdriver\chromium\webdriver.py", line 50, in __init__
    if finder.get_browser_path():
       ^^^^^^^^^^^^^^^^^^^^^^^^^
  File "C:\Users\taois\scoop\apps\anaconda3\current\App\Lib\site-packages\selenium\webdriver\common\driver_finder.py", line 47, in get_browser_path
    return self._binary_paths()["browser_path"]
           ^^^^^^^^^^^^^^^^^^^^
  File "C:\Users\taois\scoop\apps\anaconda3\current\App\Lib\site-packages\selenium\webdriver\common\driver_finder.py", line 78, in _binary_paths
    raise NoSuchDriverException(msg) from err
selenium.common.exceptions.NoSuchDriverException: Message: Unable to obtain driver for chrome; For documentation on this error, please visit: https://www.selenium.dev/documentation/webdriver/troubleshooting/errors/driver_location


2024-11-29 07:35:35,569 - Restarting the process...
2024-11-29 07:35:40,574 - Error occurred: Message: Unable to obtain driver for chrome; For documentation on this error, please visit: https://www.selenium.dev/documentation/webdriver/troubleshooting/errors/driver_location

2024-11-29 07:35:40,575 - Stack trace: Traceback (most recent call last):
  File "C:\Users\taois\scoop\apps\anaconda3\current\App\Lib\site-packages\selenium\webdriver\common\driver_finder.py", line 64, in _binary_paths
    raise ValueError(f"The path is not a valid file: {path}")
ValueError: The path is not a valid file: C:/Users/User/scoop/apps/chromedriver/current/chromedriver.exe

The above exception was the direct cause of the following exception:

Traceback (most recent call last):
  File "D:\EDA\e2\EDA\p.py", line 155, in <module>
    driver = webdriver.Chrome(service=service, options=options)
             ^^^^^^^^^^^^^^^^^^^^^^^^^^^^^^^^^^^^^^^^^^^^^^^^^^
  File "C:\Users\taois\scoop\apps\anaconda3\current\App\Lib\site-packages\selenium\webdriver\chrome\webdriver.py", line 45, in __init__
    super().__init__(
  File "C:\Users\taois\scoop\apps\anaconda3\current\App\Lib\site-packages\selenium\webdriver\chromium\webdriver.py", line 50, in __init__
    if finder.get_browser_path():
       ^^^^^^^^^^^^^^^^^^^^^^^^^
  File "C:\Users\taois\scoop\apps\anaconda3\current\App\Lib\site-packages\selenium\webdriver\common\driver_finder.py", line 47, in get_browser_path
    return self._binary_paths()["browser_path"]
           ^^^^^^^^^^^^^^^^^^^^
  File "C:\Users\taois\scoop\apps\anaconda3\current\App\Lib\site-packages\selenium\webdriver\common\driver_finder.py", line 78, in _binary_paths
    raise NoSuchDriverException(msg) from err
selenium.common.exceptions.NoSuchDriverException: Message: Unable to obtain driver for chrome; For documentation on this error, please visit: https://www.selenium.dev/documentation/webdriver/troubleshooting/errors/driver_location


2024-11-29 07:35:40,576 - Restarting the process...
2024-11-29 07:35:45,580 - Error occurred: Message: Unable to obtain driver for chrome; For documentation on this error, please visit: https://www.selenium.dev/documentation/webdriver/troubleshooting/errors/driver_location

2024-11-29 07:35:45,580 - Stack trace: Traceback (most recent call last):
  File "C:\Users\taois\scoop\apps\anaconda3\current\App\Lib\site-packages\selenium\webdriver\common\driver_finder.py", line 64, in _binary_paths
    raise ValueError(f"The path is not a valid file: {path}")
ValueError: The path is not a valid file: C:/Users/User/scoop/apps/chromedriver/current/chromedriver.exe

The above exception was the direct cause of the following exception:

Traceback (most recent call last):
  File "D:\EDA\e2\EDA\p.py", line 155, in <module>
    driver = webdriver.Chrome(service=service, options=options)
             ^^^^^^^^^^^^^^^^^^^^^^^^^^^^^^^^^^^^^^^^^^^^^^^^^^
  File "C:\Users\taois\scoop\apps\anaconda3\current\App\Lib\site-packages\selenium\webdriver\chrome\webdriver.py", line 45, in __init__
    super().__init__(
  File "C:\Users\taois\scoop\apps\anaconda3\current\App\Lib\site-packages\selenium\webdriver\chromium\webdriver.py", line 50, in __init__
    if finder.get_browser_path():
       ^^^^^^^^^^^^^^^^^^^^^^^^^
  File "C:\Users\taois\scoop\apps\anaconda3\current\App\Lib\site-packages\selenium\webdriver\common\driver_finder.py", line 47, in get_browser_path
    return self._binary_paths()["browser_path"]
           ^^^^^^^^^^^^^^^^^^^^
  File "C:\Users\taois\scoop\apps\anaconda3\current\App\Lib\site-packages\selenium\webdriver\common\driver_finder.py", line 78, in _binary_paths
    raise NoSuchDriverException(msg) from err
selenium.common.exceptions.NoSuchDriverException: Message: Unable to obtain driver for chrome; For documentation on this error, please visit: https://www.selenium.dev/documentation/webdriver/troubleshooting/errors/driver_location


2024-11-29 07:35:45,580 - Restarting the process...
2024-11-29 07:35:50,585 - Error occurred: Message: Unable to obtain driver for chrome; For documentation on this error, please visit: https://www.selenium.dev/documentation/webdriver/troubleshooting/errors/driver_location

2024-11-29 07:35:50,586 - Stack trace: Traceback (most recent call last):
  File "C:\Users\taois\scoop\apps\anaconda3\current\App\Lib\site-packages\selenium\webdriver\common\driver_finder.py", line 64, in _binary_paths
    raise ValueError(f"The path is not a valid file: {path}")
ValueError: The path is not a valid file: C:/Users/User/scoop/apps/chromedriver/current/chromedriver.exe

The above exception was the direct cause of the following exception:

Traceback (most recent call last):
  File "D:\EDA\e2\EDA\p.py", line 155, in <module>
    driver = webdriver.Chrome(service=service, options=options)
             ^^^^^^^^^^^^^^^^^^^^^^^^^^^^^^^^^^^^^^^^^^^^^^^^^^
  File "C:\Users\taois\scoop\apps\anaconda3\current\App\Lib\site-packages\selenium\webdriver\chrome\webdriver.py", line 45, in __init__
    super().__init__(
  File "C:\Users\taois\scoop\apps\anaconda3\current\App\Lib\site-packages\selenium\webdriver\chromium\webdriver.py", line 50, in __init__
    if finder.get_browser_path():
       ^^^^^^^^^^^^^^^^^^^^^^^^^
  File "C:\Users\taois\scoop\apps\anaconda3\current\App\Lib\site-packages\selenium\webdriver\common\driver_finder.py", line 47, in get_browser_path
    return self._binary_paths()["browser_path"]
           ^^^^^^^^^^^^^^^^^^^^
  File "C:\Users\taois\scoop\apps\anaconda3\current\App\Lib\site-packages\selenium\webdriver\common\driver_finder.py", line 78, in _binary_paths
    raise NoSuchDriverException(msg) from err
selenium.common.exceptions.NoSuchDriverException: Message: Unable to obtain driver for chrome; For documentation on this error, please visit: https://www.selenium.dev/documentation/webdriver/troubleshooting/errors/driver_location


2024-11-29 07:35:50,586 - Restarting the process...
2024-11-29 07:35:55,589 - Error occurred: Message: Unable to obtain driver for chrome; For documentation on this error, please visit: https://www.selenium.dev/documentation/webdriver/troubleshooting/errors/driver_location

2024-11-29 07:35:55,590 - Stack trace: Traceback (most recent call last):
  File "C:\Users\taois\scoop\apps\anaconda3\current\App\Lib\site-packages\selenium\webdriver\common\driver_finder.py", line 64, in _binary_paths
    raise ValueError(f"The path is not a valid file: {path}")
ValueError: The path is not a valid file: C:/Users/User/scoop/apps/chromedriver/current/chromedriver.exe

The above exception was the direct cause of the following exception:

Traceback (most recent call last):
  File "D:\EDA\e2\EDA\p.py", line 155, in <module>
    driver = webdriver.Chrome(service=service, options=options)
             ^^^^^^^^^^^^^^^^^^^^^^^^^^^^^^^^^^^^^^^^^^^^^^^^^^
  File "C:\Users\taois\scoop\apps\anaconda3\current\App\Lib\site-packages\selenium\webdriver\chrome\webdriver.py", line 45, in __init__
    super().__init__(
  File "C:\Users\taois\scoop\apps\anaconda3\current\App\Lib\site-packages\selenium\webdriver\chromium\webdriver.py", line 50, in __init__
    if finder.get_browser_path():
       ^^^^^^^^^^^^^^^^^^^^^^^^^
  File "C:\Users\taois\scoop\apps\anaconda3\current\App\Lib\site-packages\selenium\webdriver\common\driver_finder.py", line 47, in get_browser_path
    return self._binary_paths()["browser_path"]
           ^^^^^^^^^^^^^^^^^^^^
  File "C:\Users\taois\scoop\apps\anaconda3\current\App\Lib\site-packages\selenium\webdriver\common\driver_finder.py", line 78, in _binary_paths
    raise NoSuchDriverException(msg) from err
selenium.common.exceptions.NoSuchDriverException: Message: Unable to obtain driver for chrome; For documentation on this error, please visit: https://www.selenium.dev/documentation/webdriver/troubleshooting/errors/driver_location


2024-11-29 07:35:55,590 - Restarting the process...
2024-11-29 07:36:00,595 - Error occurred: Message: Unable to obtain driver for chrome; For documentation on this error, please visit: https://www.selenium.dev/documentation/webdriver/troubleshooting/errors/driver_location

2024-11-29 07:36:00,596 - Stack trace: Traceback (most recent call last):
  File "C:\Users\taois\scoop\apps\anaconda3\current\App\Lib\site-packages\selenium\webdriver\common\driver_finder.py", line 64, in _binary_paths
    raise ValueError(f"The path is not a valid file: {path}")
ValueError: The path is not a valid file: C:/Users/User/scoop/apps/chromedriver/current/chromedriver.exe

The above exception was the direct cause of the following exception:

Traceback (most recent call last):
  File "D:\EDA\e2\EDA\p.py", line 155, in <module>
    driver = webdriver.Chrome(service=service, options=options)
             ^^^^^^^^^^^^^^^^^^^^^^^^^^^^^^^^^^^^^^^^^^^^^^^^^^
  File "C:\Users\taois\scoop\apps\anaconda3\current\App\Lib\site-packages\selenium\webdriver\chrome\webdriver.py", line 45, in __init__
    super().__init__(
  File "C:\Users\taois\scoop\apps\anaconda3\current\App\Lib\site-packages\selenium\webdriver\chromium\webdriver.py", line 50, in __init__
    if finder.get_browser_path():
       ^^^^^^^^^^^^^^^^^^^^^^^^^
  File "C:\Users\taois\scoop\apps\anaconda3\current\App\Lib\site-packages\selenium\webdriver\common\driver_finder.py", line 47, in get_browser_path
    return self._binary_paths()["browser_path"]
           ^^^^^^^^^^^^^^^^^^^^
  File "C:\Users\taois\scoop\apps\anaconda3\current\App\Lib\site-packages\selenium\webdriver\common\driver_finder.py", line 78, in _binary_paths
    raise NoSuchDriverException(msg) from err
selenium.common.exceptions.NoSuchDriverException: Message: Unable to obtain driver for chrome; For documentation on this error, please visit: https://www.selenium.dev/documentation/webdriver/troubleshooting/errors/driver_location


2024-11-29 07:36:00,596 - Restarting the process...
2024-11-29 07:36:05,599 - Error occurred: Message: Unable to obtain driver for chrome; For documentation on this error, please visit: https://www.selenium.dev/documentation/webdriver/troubleshooting/errors/driver_location

2024-11-29 07:36:05,600 - Stack trace: Traceback (most recent call last):
  File "C:\Users\taois\scoop\apps\anaconda3\current\App\Lib\site-packages\selenium\webdriver\common\driver_finder.py", line 64, in _binary_paths
    raise ValueError(f"The path is not a valid file: {path}")
ValueError: The path is not a valid file: C:/Users/User/scoop/apps/chromedriver/current/chromedriver.exe

The above exception was the direct cause of the following exception:

Traceback (most recent call last):
  File "D:\EDA\e2\EDA\p.py", line 155, in <module>
    driver = webdriver.Chrome(service=service, options=options)
             ^^^^^^^^^^^^^^^^^^^^^^^^^^^^^^^^^^^^^^^^^^^^^^^^^^
  File "C:\Users\taois\scoop\apps\anaconda3\current\App\Lib\site-packages\selenium\webdriver\chrome\webdriver.py", line 45, in __init__
    super().__init__(
  File "C:\Users\taois\scoop\apps\anaconda3\current\App\Lib\site-packages\selenium\webdriver\chromium\webdriver.py", line 50, in __init__
    if finder.get_browser_path():
       ^^^^^^^^^^^^^^^^^^^^^^^^^
  File "C:\Users\taois\scoop\apps\anaconda3\current\App\Lib\site-packages\selenium\webdriver\common\driver_finder.py", line 47, in get_browser_path
    return self._binary_paths()["browser_path"]
           ^^^^^^^^^^^^^^^^^^^^
  File "C:\Users\taois\scoop\apps\anaconda3\current\App\Lib\site-packages\selenium\webdriver\common\driver_finder.py", line 78, in _binary_paths
    raise NoSuchDriverException(msg) from err
selenium.common.exceptions.NoSuchDriverException: Message: Unable to obtain driver for chrome; For documentation on this error, please visit: https://www.selenium.dev/documentation/webdriver/troubleshooting/errors/driver_location


2024-11-29 07:36:05,600 - Restarting the process...
2024-11-29 07:36:10,604 - Error occurred: Message: Unable to obtain driver for chrome; For documentation on this error, please visit: https://www.selenium.dev/documentation/webdriver/troubleshooting/errors/driver_location

2024-11-29 07:36:10,605 - Stack trace: Traceback (most recent call last):
  File "C:\Users\taois\scoop\apps\anaconda3\current\App\Lib\site-packages\selenium\webdriver\common\driver_finder.py", line 64, in _binary_paths
    raise ValueError(f"The path is not a valid file: {path}")
ValueError: The path is not a valid file: C:/Users/User/scoop/apps/chromedriver/current/chromedriver.exe

The above exception was the direct cause of the following exception:

Traceback (most recent call last):
  File "D:\EDA\e2\EDA\p.py", line 155, in <module>
    driver = webdriver.Chrome(service=service, options=options)
             ^^^^^^^^^^^^^^^^^^^^^^^^^^^^^^^^^^^^^^^^^^^^^^^^^^
  File "C:\Users\taois\scoop\apps\anaconda3\current\App\Lib\site-packages\selenium\webdriver\chrome\webdriver.py", line 45, in __init__
    super().__init__(
  File "C:\Users\taois\scoop\apps\anaconda3\current\App\Lib\site-packages\selenium\webdriver\chromium\webdriver.py", line 50, in __init__
    if finder.get_browser_path():
       ^^^^^^^^^^^^^^^^^^^^^^^^^
  File "C:\Users\taois\scoop\apps\anaconda3\current\App\Lib\site-packages\selenium\webdriver\common\driver_finder.py", line 47, in get_browser_path
    return self._binary_paths()["browser_path"]
           ^^^^^^^^^^^^^^^^^^^^
  File "C:\Users\taois\scoop\apps\anaconda3\current\App\Lib\site-packages\selenium\webdriver\common\driver_finder.py", line 78, in _binary_paths
    raise NoSuchDriverException(msg) from err
selenium.common.exceptions.NoSuchDriverException: Message: Unable to obtain driver for chrome; For documentation on this error, please visit: https://www.selenium.dev/documentation/webdriver/troubleshooting/errors/driver_location


2024-11-29 07:36:10,605 - Restarting the process...
2024-11-29 07:36:15,609 - Error occurred: Message: Unable to obtain driver for chrome; For documentation on this error, please visit: https://www.selenium.dev/documentation/webdriver/troubleshooting/errors/driver_location

2024-11-29 07:36:15,610 - Stack trace: Traceback (most recent call last):
  File "C:\Users\taois\scoop\apps\anaconda3\current\App\Lib\site-packages\selenium\webdriver\common\driver_finder.py", line 64, in _binary_paths
    raise ValueError(f"The path is not a valid file: {path}")
ValueError: The path is not a valid file: C:/Users/User/scoop/apps/chromedriver/current/chromedriver.exe

The above exception was the direct cause of the following exception:

Traceback (most recent call last):
  File "D:\EDA\e2\EDA\p.py", line 155, in <module>
    driver = webdriver.Chrome(service=service, options=options)
             ^^^^^^^^^^^^^^^^^^^^^^^^^^^^^^^^^^^^^^^^^^^^^^^^^^
  File "C:\Users\taois\scoop\apps\anaconda3\current\App\Lib\site-packages\selenium\webdriver\chrome\webdriver.py", line 45, in __init__
    super().__init__(
  File "C:\Users\taois\scoop\apps\anaconda3\current\App\Lib\site-packages\selenium\webdriver\chromium\webdriver.py", line 50, in __init__
    if finder.get_browser_path():
       ^^^^^^^^^^^^^^^^^^^^^^^^^
  File "C:\Users\taois\scoop\apps\anaconda3\current\App\Lib\site-packages\selenium\webdriver\common\driver_finder.py", line 47, in get_browser_path
    return self._binary_paths()["browser_path"]
           ^^^^^^^^^^^^^^^^^^^^
  File "C:\Users\taois\scoop\apps\anaconda3\current\App\Lib\site-packages\selenium\webdriver\common\driver_finder.py", line 78, in _binary_paths
    raise NoSuchDriverException(msg) from err
selenium.common.exceptions.NoSuchDriverException: Message: Unable to obtain driver for chrome; For documentation on this error, please visit: https://www.selenium.dev/documentation/webdriver/troubleshooting/errors/driver_location


2024-11-29 07:36:15,610 - Restarting the process...
2024-11-29 07:36:20,614 - Error occurred: Message: Unable to obtain driver for chrome; For documentation on this error, please visit: https://www.selenium.dev/documentation/webdriver/troubleshooting/errors/driver_location

2024-11-29 07:36:20,615 - Stack trace: Traceback (most recent call last):
  File "C:\Users\taois\scoop\apps\anaconda3\current\App\Lib\site-packages\selenium\webdriver\common\driver_finder.py", line 64, in _binary_paths
    raise ValueError(f"The path is not a valid file: {path}")
ValueError: The path is not a valid file: C:/Users/User/scoop/apps/chromedriver/current/chromedriver.exe

The above exception was the direct cause of the following exception:

Traceback (most recent call last):
  File "D:\EDA\e2\EDA\p.py", line 155, in <module>
    driver = webdriver.Chrome(service=service, options=options)
             ^^^^^^^^^^^^^^^^^^^^^^^^^^^^^^^^^^^^^^^^^^^^^^^^^^
  File "C:\Users\taois\scoop\apps\anaconda3\current\App\Lib\site-packages\selenium\webdriver\chrome\webdriver.py", line 45, in __init__
    super().__init__(
  File "C:\Users\taois\scoop\apps\anaconda3\current\App\Lib\site-packages\selenium\webdriver\chromium\webdriver.py", line 50, in __init__
    if finder.get_browser_path():
       ^^^^^^^^^^^^^^^^^^^^^^^^^
  File "C:\Users\taois\scoop\apps\anaconda3\current\App\Lib\site-packages\selenium\webdriver\common\driver_finder.py", line 47, in get_browser_path
    return self._binary_paths()["browser_path"]
           ^^^^^^^^^^^^^^^^^^^^
  File "C:\Users\taois\scoop\apps\anaconda3\current\App\Lib\site-packages\selenium\webdriver\common\driver_finder.py", line 78, in _binary_paths
    raise NoSuchDriverException(msg) from err
selenium.common.exceptions.NoSuchDriverException: Message: Unable to obtain driver for chrome; For documentation on this error, please visit: https://www.selenium.dev/documentation/webdriver/troubleshooting/errors/driver_location


2024-11-29 07:36:20,615 - Restarting the process...
2024-11-29 07:36:25,619 - Error occurred: Message: Unable to obtain driver for chrome; For documentation on this error, please visit: https://www.selenium.dev/documentation/webdriver/troubleshooting/errors/driver_location

2024-11-29 07:36:25,620 - Stack trace: Traceback (most recent call last):
  File "C:\Users\taois\scoop\apps\anaconda3\current\App\Lib\site-packages\selenium\webdriver\common\driver_finder.py", line 64, in _binary_paths
    raise ValueError(f"The path is not a valid file: {path}")
ValueError: The path is not a valid file: C:/Users/User/scoop/apps/chromedriver/current/chromedriver.exe

The above exception was the direct cause of the following exception:

Traceback (most recent call last):
  File "D:\EDA\e2\EDA\p.py", line 155, in <module>
    driver = webdriver.Chrome(service=service, options=options)
             ^^^^^^^^^^^^^^^^^^^^^^^^^^^^^^^^^^^^^^^^^^^^^^^^^^
  File "C:\Users\taois\scoop\apps\anaconda3\current\App\Lib\site-packages\selenium\webdriver\chrome\webdriver.py", line 45, in __init__
    super().__init__(
  File "C:\Users\taois\scoop\apps\anaconda3\current\App\Lib\site-packages\selenium\webdriver\chromium\webdriver.py", line 50, in __init__
    if finder.get_browser_path():
       ^^^^^^^^^^^^^^^^^^^^^^^^^
  File "C:\Users\taois\scoop\apps\anaconda3\current\App\Lib\site-packages\selenium\webdriver\common\driver_finder.py", line 47, in get_browser_path
    return self._binary_paths()["browser_path"]
           ^^^^^^^^^^^^^^^^^^^^
  File "C:\Users\taois\scoop\apps\anaconda3\current\App\Lib\site-packages\selenium\webdriver\common\driver_finder.py", line 78, in _binary_paths
    raise NoSuchDriverException(msg) from err
selenium.common.exceptions.NoSuchDriverException: Message: Unable to obtain driver for chrome; For documentation on this error, please visit: https://www.selenium.dev/documentation/webdriver/troubleshooting/errors/driver_location


2024-11-29 07:36:25,620 - Restarting the process...
2024-11-29 07:36:30,623 - Error occurred: Message: Unable to obtain driver for chrome; For documentation on this error, please visit: https://www.selenium.dev/documentation/webdriver/troubleshooting/errors/driver_location

2024-11-29 07:36:30,624 - Stack trace: Traceback (most recent call last):
  File "C:\Users\taois\scoop\apps\anaconda3\current\App\Lib\site-packages\selenium\webdriver\common\driver_finder.py", line 64, in _binary_paths
    raise ValueError(f"The path is not a valid file: {path}")
ValueError: The path is not a valid file: C:/Users/User/scoop/apps/chromedriver/current/chromedriver.exe

The above exception was the direct cause of the following exception:

Traceback (most recent call last):
  File "D:\EDA\e2\EDA\p.py", line 155, in <module>
    driver = webdriver.Chrome(service=service, options=options)
             ^^^^^^^^^^^^^^^^^^^^^^^^^^^^^^^^^^^^^^^^^^^^^^^^^^
  File "C:\Users\taois\scoop\apps\anaconda3\current\App\Lib\site-packages\selenium\webdriver\chrome\webdriver.py", line 45, in __init__
    super().__init__(
  File "C:\Users\taois\scoop\apps\anaconda3\current\App\Lib\site-packages\selenium\webdriver\chromium\webdriver.py", line 50, in __init__
    if finder.get_browser_path():
       ^^^^^^^^^^^^^^^^^^^^^^^^^
  File "C:\Users\taois\scoop\apps\anaconda3\current\App\Lib\site-packages\selenium\webdriver\common\driver_finder.py", line 47, in get_browser_path
    return self._binary_paths()["browser_path"]
           ^^^^^^^^^^^^^^^^^^^^
  File "C:\Users\taois\scoop\apps\anaconda3\current\App\Lib\site-packages\selenium\webdriver\common\driver_finder.py", line 78, in _binary_paths
    raise NoSuchDriverException(msg) from err
selenium.common.exceptions.NoSuchDriverException: Message: Unable to obtain driver for chrome; For documentation on this error, please visit: https://www.selenium.dev/documentation/webdriver/troubleshooting/errors/driver_location


2024-11-29 07:36:30,624 - Restarting the process...
2024-11-29 07:36:35,629 - Error occurred: Message: Unable to obtain driver for chrome; For documentation on this error, please visit: https://www.selenium.dev/documentation/webdriver/troubleshooting/errors/driver_location

2024-11-29 07:36:35,630 - Stack trace: Traceback (most recent call last):
  File "C:\Users\taois\scoop\apps\anaconda3\current\App\Lib\site-packages\selenium\webdriver\common\driver_finder.py", line 64, in _binary_paths
    raise ValueError(f"The path is not a valid file: {path}")
ValueError: The path is not a valid file: C:/Users/User/scoop/apps/chromedriver/current/chromedriver.exe

The above exception was the direct cause of the following exception:

Traceback (most recent call last):
  File "D:\EDA\e2\EDA\p.py", line 155, in <module>
    driver = webdriver.Chrome(service=service, options=options)
             ^^^^^^^^^^^^^^^^^^^^^^^^^^^^^^^^^^^^^^^^^^^^^^^^^^
  File "C:\Users\taois\scoop\apps\anaconda3\current\App\Lib\site-packages\selenium\webdriver\chrome\webdriver.py", line 45, in __init__
    super().__init__(
  File "C:\Users\taois\scoop\apps\anaconda3\current\App\Lib\site-packages\selenium\webdriver\chromium\webdriver.py", line 50, in __init__
    if finder.get_browser_path():
       ^^^^^^^^^^^^^^^^^^^^^^^^^
  File "C:\Users\taois\scoop\apps\anaconda3\current\App\Lib\site-packages\selenium\webdriver\common\driver_finder.py", line 47, in get_browser_path
    return self._binary_paths()["browser_path"]
           ^^^^^^^^^^^^^^^^^^^^
  File "C:\Users\taois\scoop\apps\anaconda3\current\App\Lib\site-packages\selenium\webdriver\common\driver_finder.py", line 78, in _binary_paths
    raise NoSuchDriverException(msg) from err
selenium.common.exceptions.NoSuchDriverException: Message: Unable to obtain driver for chrome; For documentation on this error, please visit: https://www.selenium.dev/documentation/webdriver/troubleshooting/errors/driver_location


2024-11-29 07:36:35,630 - Restarting the process...
2024-11-29 07:36:40,634 - Error occurred: Message: Unable to obtain driver for chrome; For documentation on this error, please visit: https://www.selenium.dev/documentation/webdriver/troubleshooting/errors/driver_location

2024-11-29 07:36:40,634 - Stack trace: Traceback (most recent call last):
  File "C:\Users\taois\scoop\apps\anaconda3\current\App\Lib\site-packages\selenium\webdriver\common\driver_finder.py", line 64, in _binary_paths
    raise ValueError(f"The path is not a valid file: {path}")
ValueError: The path is not a valid file: C:/Users/User/scoop/apps/chromedriver/current/chromedriver.exe

The above exception was the direct cause of the following exception:

Traceback (most recent call last):
  File "D:\EDA\e2\EDA\p.py", line 155, in <module>
    driver = webdriver.Chrome(service=service, options=options)
             ^^^^^^^^^^^^^^^^^^^^^^^^^^^^^^^^^^^^^^^^^^^^^^^^^^
  File "C:\Users\taois\scoop\apps\anaconda3\current\App\Lib\site-packages\selenium\webdriver\chrome\webdriver.py", line 45, in __init__
    super().__init__(
  File "C:\Users\taois\scoop\apps\anaconda3\current\App\Lib\site-packages\selenium\webdriver\chromium\webdriver.py", line 50, in __init__
    if finder.get_browser_path():
       ^^^^^^^^^^^^^^^^^^^^^^^^^
  File "C:\Users\taois\scoop\apps\anaconda3\current\App\Lib\site-packages\selenium\webdriver\common\driver_finder.py", line 47, in get_browser_path
    return self._binary_paths()["browser_path"]
           ^^^^^^^^^^^^^^^^^^^^
  File "C:\Users\taois\scoop\apps\anaconda3\current\App\Lib\site-packages\selenium\webdriver\common\driver_finder.py", line 78, in _binary_paths
    raise NoSuchDriverException(msg) from err
selenium.common.exceptions.NoSuchDriverException: Message: Unable to obtain driver for chrome; For documentation on this error, please visit: https://www.selenium.dev/documentation/webdriver/troubleshooting/errors/driver_location


2024-11-29 07:36:40,635 - Restarting the process...
2024-11-29 07:36:45,639 - Error occurred: Message: Unable to obtain driver for chrome; For documentation on this error, please visit: https://www.selenium.dev/documentation/webdriver/troubleshooting/errors/driver_location

2024-11-29 07:36:45,639 - Stack trace: Traceback (most recent call last):
  File "C:\Users\taois\scoop\apps\anaconda3\current\App\Lib\site-packages\selenium\webdriver\common\driver_finder.py", line 64, in _binary_paths
    raise ValueError(f"The path is not a valid file: {path}")
ValueError: The path is not a valid file: C:/Users/User/scoop/apps/chromedriver/current/chromedriver.exe

The above exception was the direct cause of the following exception:

Traceback (most recent call last):
  File "D:\EDA\e2\EDA\p.py", line 155, in <module>
    driver = webdriver.Chrome(service=service, options=options)
             ^^^^^^^^^^^^^^^^^^^^^^^^^^^^^^^^^^^^^^^^^^^^^^^^^^
  File "C:\Users\taois\scoop\apps\anaconda3\current\App\Lib\site-packages\selenium\webdriver\chrome\webdriver.py", line 45, in __init__
    super().__init__(
  File "C:\Users\taois\scoop\apps\anaconda3\current\App\Lib\site-packages\selenium\webdriver\chromium\webdriver.py", line 50, in __init__
    if finder.get_browser_path():
       ^^^^^^^^^^^^^^^^^^^^^^^^^
  File "C:\Users\taois\scoop\apps\anaconda3\current\App\Lib\site-packages\selenium\webdriver\common\driver_finder.py", line 47, in get_browser_path
    return self._binary_paths()["browser_path"]
           ^^^^^^^^^^^^^^^^^^^^
  File "C:\Users\taois\scoop\apps\anaconda3\current\App\Lib\site-packages\selenium\webdriver\common\driver_finder.py", line 78, in _binary_paths
    raise NoSuchDriverException(msg) from err
selenium.common.exceptions.NoSuchDriverException: Message: Unable to obtain driver for chrome; For documentation on this error, please visit: https://www.selenium.dev/documentation/webdriver/troubleshooting/errors/driver_location


2024-11-29 07:36:45,639 - Restarting the process...
2024-11-29 07:37:20,887 - Error occurred: Message: Unable to obtain driver for chrome; For documentation on this error, please visit: https://www.selenium.dev/documentation/webdriver/troubleshooting/errors/driver_location

2024-11-29 07:37:20,890 - Stack trace: Traceback (most recent call last):
  File "C:\Users\taois\scoop\apps\anaconda3\current\App\Lib\site-packages\selenium\webdriver\common\driver_finder.py", line 64, in _binary_paths
    raise ValueError(f"The path is not a valid file: {path}")
ValueError: The path is not a valid file: C:/Users/User/scoop/apps/chromedriver/current/chromedriver.exe

The above exception was the direct cause of the following exception:

Traceback (most recent call last):
  File "D:\EDA\e2\EDA\p.py", line 155, in <module>
    driver = webdriver.Chrome(service=service, options=options)
             ^^^^^^^^^^^^^^^^^^^^^^^^^^^^^^^^^^^^^^^^^^^^^^^^^^
  File "C:\Users\taois\scoop\apps\anaconda3\current\App\Lib\site-packages\selenium\webdriver\chrome\webdriver.py", line 45, in __init__
    super().__init__(
  File "C:\Users\taois\scoop\apps\anaconda3\current\App\Lib\site-packages\selenium\webdriver\chromium\webdriver.py", line 50, in __init__
    if finder.get_browser_path():
       ^^^^^^^^^^^^^^^^^^^^^^^^^
  File "C:\Users\taois\scoop\apps\anaconda3\current\App\Lib\site-packages\selenium\webdriver\common\driver_finder.py", line 47, in get_browser_path
    return self._binary_paths()["browser_path"]
           ^^^^^^^^^^^^^^^^^^^^
  File "C:\Users\taois\scoop\apps\anaconda3\current\App\Lib\site-packages\selenium\webdriver\common\driver_finder.py", line 78, in _binary_paths
    raise NoSuchDriverException(msg) from err
selenium.common.exceptions.NoSuchDriverException: Message: Unable to obtain driver for chrome; For documentation on this error, please visit: https://www.selenium.dev/documentation/webdriver/troubleshooting/errors/driver_location


2024-11-29 07:37:20,891 - Restarting the process...
2024-11-29 07:37:25,894 - Error occurred: Message: Unable to obtain driver for chrome; For documentation on this error, please visit: https://www.selenium.dev/documentation/webdriver/troubleshooting/errors/driver_location

2024-11-29 07:37:25,894 - Stack trace: Traceback (most recent call last):
  File "C:\Users\taois\scoop\apps\anaconda3\current\App\Lib\site-packages\selenium\webdriver\common\driver_finder.py", line 64, in _binary_paths
    raise ValueError(f"The path is not a valid file: {path}")
ValueError: The path is not a valid file: C:/Users/User/scoop/apps/chromedriver/current/chromedriver.exe

The above exception was the direct cause of the following exception:

Traceback (most recent call last):
  File "D:\EDA\e2\EDA\p.py", line 155, in <module>
    driver = webdriver.Chrome(service=service, options=options)
             ^^^^^^^^^^^^^^^^^^^^^^^^^^^^^^^^^^^^^^^^^^^^^^^^^^
  File "C:\Users\taois\scoop\apps\anaconda3\current\App\Lib\site-packages\selenium\webdriver\chrome\webdriver.py", line 45, in __init__
    super().__init__(
  File "C:\Users\taois\scoop\apps\anaconda3\current\App\Lib\site-packages\selenium\webdriver\chromium\webdriver.py", line 50, in __init__
    if finder.get_browser_path():
       ^^^^^^^^^^^^^^^^^^^^^^^^^
  File "C:\Users\taois\scoop\apps\anaconda3\current\App\Lib\site-packages\selenium\webdriver\common\driver_finder.py", line 47, in get_browser_path
    return self._binary_paths()["browser_path"]
           ^^^^^^^^^^^^^^^^^^^^
  File "C:\Users\taois\scoop\apps\anaconda3\current\App\Lib\site-packages\selenium\webdriver\common\driver_finder.py", line 78, in _binary_paths
    raise NoSuchDriverException(msg) from err
selenium.common.exceptions.NoSuchDriverException: Message: Unable to obtain driver for chrome; For documentation on this error, please visit: https://www.selenium.dev/documentation/webdriver/troubleshooting/errors/driver_location


2024-11-29 07:37:25,895 - Restarting the process...
2024-11-29 07:37:30,900 - Error occurred: Message: Unable to obtain driver for chrome; For documentation on this error, please visit: https://www.selenium.dev/documentation/webdriver/troubleshooting/errors/driver_location

2024-11-29 07:37:30,901 - Stack trace: Traceback (most recent call last):
  File "C:\Users\taois\scoop\apps\anaconda3\current\App\Lib\site-packages\selenium\webdriver\common\driver_finder.py", line 64, in _binary_paths
    raise ValueError(f"The path is not a valid file: {path}")
ValueError: The path is not a valid file: C:/Users/User/scoop/apps/chromedriver/current/chromedriver.exe

The above exception was the direct cause of the following exception:

Traceback (most recent call last):
  File "D:\EDA\e2\EDA\p.py", line 155, in <module>
    driver = webdriver.Chrome(service=service, options=options)
             ^^^^^^^^^^^^^^^^^^^^^^^^^^^^^^^^^^^^^^^^^^^^^^^^^^
  File "C:\Users\taois\scoop\apps\anaconda3\current\App\Lib\site-packages\selenium\webdriver\chrome\webdriver.py", line 45, in __init__
    super().__init__(
  File "C:\Users\taois\scoop\apps\anaconda3\current\App\Lib\site-packages\selenium\webdriver\chromium\webdriver.py", line 50, in __init__
    if finder.get_browser_path():
       ^^^^^^^^^^^^^^^^^^^^^^^^^
  File "C:\Users\taois\scoop\apps\anaconda3\current\App\Lib\site-packages\selenium\webdriver\common\driver_finder.py", line 47, in get_browser_path
    return self._binary_paths()["browser_path"]
           ^^^^^^^^^^^^^^^^^^^^
  File "C:\Users\taois\scoop\apps\anaconda3\current\App\Lib\site-packages\selenium\webdriver\common\driver_finder.py", line 78, in _binary_paths
    raise NoSuchDriverException(msg) from err
selenium.common.exceptions.NoSuchDriverException: Message: Unable to obtain driver for chrome; For documentation on this error, please visit: https://www.selenium.dev/documentation/webdriver/troubleshooting/errors/driver_location


2024-11-29 07:37:30,901 - Restarting the process...
2024-11-29 07:37:35,906 - Error occurred: Message: Unable to obtain driver for chrome; For documentation on this error, please visit: https://www.selenium.dev/documentation/webdriver/troubleshooting/errors/driver_location

2024-11-29 07:37:35,907 - Stack trace: Traceback (most recent call last):
  File "C:\Users\taois\scoop\apps\anaconda3\current\App\Lib\site-packages\selenium\webdriver\common\driver_finder.py", line 64, in _binary_paths
    raise ValueError(f"The path is not a valid file: {path}")
ValueError: The path is not a valid file: C:/Users/User/scoop/apps/chromedriver/current/chromedriver.exe

The above exception was the direct cause of the following exception:

Traceback (most recent call last):
  File "D:\EDA\e2\EDA\p.py", line 155, in <module>
    driver = webdriver.Chrome(service=service, options=options)
             ^^^^^^^^^^^^^^^^^^^^^^^^^^^^^^^^^^^^^^^^^^^^^^^^^^
  File "C:\Users\taois\scoop\apps\anaconda3\current\App\Lib\site-packages\selenium\webdriver\chrome\webdriver.py", line 45, in __init__
    super().__init__(
  File "C:\Users\taois\scoop\apps\anaconda3\current\App\Lib\site-packages\selenium\webdriver\chromium\webdriver.py", line 50, in __init__
    if finder.get_browser_path():
       ^^^^^^^^^^^^^^^^^^^^^^^^^
  File "C:\Users\taois\scoop\apps\anaconda3\current\App\Lib\site-packages\selenium\webdriver\common\driver_finder.py", line 47, in get_browser_path
    return self._binary_paths()["browser_path"]
           ^^^^^^^^^^^^^^^^^^^^
  File "C:\Users\taois\scoop\apps\anaconda3\current\App\Lib\site-packages\selenium\webdriver\common\driver_finder.py", line 78, in _binary_paths
    raise NoSuchDriverException(msg) from err
selenium.common.exceptions.NoSuchDriverException: Message: Unable to obtain driver for chrome; For documentation on this error, please visit: https://www.selenium.dev/documentation/webdriver/troubleshooting/errors/driver_location


2024-11-29 07:37:35,907 - Restarting the process...
2024-11-29 07:37:40,913 - Error occurred: Message: Unable to obtain driver for chrome; For documentation on this error, please visit: https://www.selenium.dev/documentation/webdriver/troubleshooting/errors/driver_location

2024-11-29 07:37:40,914 - Stack trace: Traceback (most recent call last):
  File "C:\Users\taois\scoop\apps\anaconda3\current\App\Lib\site-packages\selenium\webdriver\common\driver_finder.py", line 64, in _binary_paths
    raise ValueError(f"The path is not a valid file: {path}")
ValueError: The path is not a valid file: C:/Users/User/scoop/apps/chromedriver/current/chromedriver.exe

The above exception was the direct cause of the following exception:

Traceback (most recent call last):
  File "D:\EDA\e2\EDA\p.py", line 155, in <module>
    driver = webdriver.Chrome(service=service, options=options)
             ^^^^^^^^^^^^^^^^^^^^^^^^^^^^^^^^^^^^^^^^^^^^^^^^^^
  File "C:\Users\taois\scoop\apps\anaconda3\current\App\Lib\site-packages\selenium\webdriver\chrome\webdriver.py", line 45, in __init__
    super().__init__(
  File "C:\Users\taois\scoop\apps\anaconda3\current\App\Lib\site-packages\selenium\webdriver\chromium\webdriver.py", line 50, in __init__
    if finder.get_browser_path():
       ^^^^^^^^^^^^^^^^^^^^^^^^^
  File "C:\Users\taois\scoop\apps\anaconda3\current\App\Lib\site-packages\selenium\webdriver\common\driver_finder.py", line 47, in get_browser_path
    return self._binary_paths()["browser_path"]
           ^^^^^^^^^^^^^^^^^^^^
  File "C:\Users\taois\scoop\apps\anaconda3\current\App\Lib\site-packages\selenium\webdriver\common\driver_finder.py", line 78, in _binary_paths
    raise NoSuchDriverException(msg) from err
selenium.common.exceptions.NoSuchDriverException: Message: Unable to obtain driver for chrome; For documentation on this error, please visit: https://www.selenium.dev/documentation/webdriver/troubleshooting/errors/driver_location


2024-11-29 07:37:40,915 - Restarting the process...
